<?xml version="1.0" encoding="utf-8"?>
<!-- =================================================================================== -->
<!-- |    This document was autogenerated by xacro from hunter_v1_sim.xacro            | -->
<!-- |    EDITING THIS FILE BY HAND IS NOT RECOMMENDED                                 | -->
<!-- =================================================================================== -->
<robot name="hunter_v1">
  <!-- Base link -->
  <link name="base_link">
    <visual>
      <origin rpy="0 0 0" xyz="0 0 0"/>
      <geometry>
        <mesh filename="package://hunter_description/meshes/base_link.dae"/>
      </geometry>
    </visual>
    <visual>
      <origin rpy="0 0 0" xyz="0 0 0.12"/>
      <geometry>
        <box size="0.75 0.15 0.08"/>
      </geometry>
    </visual>
    <visual>
      <origin rpy="0 0 0" xyz="0.17 0 0.06"/>
      <geometry>
        <box size="0.45 0.37 0.18"/>
      </geometry>
    </visual>
    <collision>
      <origin rpy="0 0 0" xyz="0.29 0 0.05"/>
      <geometry>
        <box size="0.25 0.38 0.26"/>
      </geometry>
    </collision>
    <collision>
      <origin rpy="0 0 0" xyz="-0.1 0 0.07"/>
      <geometry>
        <box size="0.56 0.38 0.22"/>
      </geometry>
    </collision>
    <inertial>
      <mass value="40"/>
      <origin xyz="0.0 0.0 0.0"/>
      <inertia ixx="2.288641" ixy="0" ixz="0" iyy="5.103976" iyz="0" izz="3.431465"/>
    </inertial>
  </link>
  <link name="base_footprint"/>
  <joint name="base_footprint_joint" type="fixed">
    <origin rpy="0 0 0" xyz="0 0 -0.18109"/>
    <parent link="base_link"/>
    <child link="base_footprint"/>
  </joint>
  <!-- front right wheel -->
  <joint name="front_right_steering" type="revolute">
    <origin rpy="0 0 0" xyz="-0.324285 0.22 -0.0165"/>
    <parent link="base_link"/>
    <child link="front_right_steer_link"/>
    <axis rpy="0 0 0" xyz="0 0 1"/>
    <limit effort="20" lower="-0.785" upper="0.785" velocity="0.8"/>
  </joint>
  <link name="front_right_steer_link">
    <inertial>
      <mass value="3"/>
      <origin xyz="0 0 0"/>
      <inertia ixx="0.7171" ixy="0" ixz="0" iyy="0.1361" iyz="0" izz="0.7171"/>
    </inertial>
    <visual>
      <origin rpy="0 0 0" xyz="0 0.06 0"/>
      <geometry>
        <mesh filename="package://hunter_description/meshes/steer_conn_fr.dae"/>
      </geometry>
    </visual>
  </link>
  <joint name="front_right_wheel" type="continuous">
    <origin rpy="0 0 0" xyz="0 0.06 0"/>
    <parent link="front_right_steer_link"/>
    <child link="front_right_wheel_link"/>
    <axis rpy="0 0 0" xyz="0 -1 0"/>
  </joint>
  <link name="front_right_wheel_link">
    <inertial>
      <mass value="3"/>
      <origin xyz="0 0 0"/>
      <inertia ixx="0.7171" ixy="0" ixz="0" iyy="0.1361" iyz="0" izz="0.7171"/>
    </inertial>
    <visual>
      <origin rpy="0 0 0" xyz="0 0 0"/>
      <geometry>
        <mesh filename="package://hunter_description/meshes/wheel_fr.dae"/>
      </geometry>
    </visual>
    <visual>
      <origin rpy="0 0 0" xyz="0 0 0"/>
      <geometry>
        <mesh filename="package://hunter_description/meshes/hub_shape.stl"/>
      </geometry>
    </visual>
    <collision>
      <origin rpy="1.570795 0 0" xyz="0 0 0"/>
      <geometry>
        <cylinder length="0.11653" radius="0.16459"/>
      </geometry>
    </collision>
  </link>
  <!-- front left wheel -->
  <joint name="front_left_steering" type="revolute">
    <origin rpy="0 0 0" xyz="-0.324285 -0.22 -0.0165"/>
    <parent link="base_link"/>
    <child link="front_left_steer_link"/>
    <axis rpy="0 0 0" xyz="0 0 1"/>
    <limit effort="20" lower="-0.785" upper="0.785" velocity="0.8"/>
  </joint>
  <link name="front_left_steer_link">
    <inertial>
      <mass value="3"/>
      <origin xyz="0 0 0"/>
      <inertia ixx="0.7171" ixy="0" ixz="0" iyy="0.1361" iyz="0" izz="0.7171"/>
    </inertial>
    <visual>
      <origin rpy="0 0 0" xyz="0 -0.06 0"/>
      <geometry>
        <mesh filename="package://hunter_description/meshes/steer_conn_fl.dae"/>
      </geometry>
    </visual>
  </link>
  <joint name="front_left_wheel" type="continuous">
    <origin rpy="0 0 0" xyz="0 -0.06 0"/>
    <parent link="front_left_steer_link"/>
    <child link="front_left_wheel_link"/>
    <axis rpy="0 0 0" xyz="0 -1 0"/>
  </joint>
  <link name="front_left_wheel_link">
    <inertial>
      <mass value="3"/>
      <origin xyz="0 0 0"/>
      <inertia ixx="0.7171" ixy="0" ixz="0" iyy="0.1361" iyz="0" izz="0.7171"/>
    </inertial>
    <visual>
      <origin rpy="0 0 0" xyz="0 0 0"/>
      <geometry>
        <mesh filename="package://hunter_description/meshes/wheel_fl.dae"/>
      </geometry>
    </visual>
    <visual>
      <origin rpy="0 0 3.14" xyz="0 0 0"/>
      <geometry>
        <mesh filename="package://hunter_description/meshes/hub_shape.stl"/>
      </geometry>
    </visual>
    <collision>
      <origin rpy="1.570795 0 0" xyz="0 0 0"/>
      <geometry>
        <cylinder length="0.11653" radius="0.16459"/>
      </geometry>
    </collision>
  </link>
  <!-- rear left wheel -->
  <link name="rear_left_wheel_link">
    <inertial>
      <mass value="3"/>
      <origin xyz="0 0 0"/>
      <inertia ixx="0.7171" ixy="0" ixz="0" iyy="0.1361" iyz="0" izz="0.7171"/>
    </inertial>
    <visual>
      <origin rpy="0 0 0" xyz="0 0 0"/>
      <geometry>
        <mesh filename="package://hunter_description/meshes/wheel_rl.dae"/>
      </geometry>
    </visual>
    <visual>
      <origin rpy="0 0 3.14" xyz="0 0 0"/>
      <geometry>
        <mesh filename="package://hunter_description/meshes/hub_shape.stl"/>
      </geometry>
    </visual>
    <collision>
      <origin rpy="1.570795 0 0" xyz="0 0 0"/>
      <geometry>
        <cylinder length="0.11653" radius="0.16459"/>
      </geometry>
    </collision>
  </link>
  <joint name="rear_left_wheel" type="continuous">
    <origin rpy="0 0 0" xyz="0.324285 -0.28 -0.0165"/>
    <parent link="base_link"/>
    <child link="rear_left_wheel_link"/>
    <axis rpy="0 0 0" xyz="0 -1 0"/>
  </joint>
  <!-- rear right wheel -->
  <link name="rear_right_wheel_link">
    <inertial>
      <mass value="3"/>
      <origin xyz="0 0 0"/>
      <inertia ixx="0.7171" ixy="0" ixz="0" iyy="0.1361" iyz="0" izz="0.7171"/>
    </inertial>
    <visual>
      <origin rpy="0 0 0" xyz="0 0 0"/>
      <geometry>
        <mesh filename="package://hunter_description/meshes/wheel_rr.dae"/>
      </geometry>
    </visual>
    <visual>
      <origin rpy="0 0 0" xyz="0 0 0"/>
      <geometry>
        <mesh filename="package://hunter_description/meshes/hub_shape.stl"/>
      </geometry>
    </visual>
    <collision>
      <origin rpy="1.570795 0 0" xyz="0 0 0"/>
      <geometry>
        <cylinder length="0.11653" radius="0.16459"/>
      </geometry>
    </collision>
  </link>
  <joint name="rear_right_wheel" type="continuous">
    <origin rpy="0 0 0" xyz="0.324285 0.28 -0.0165"/>
    <parent link="base_link"/>
    <child link="rear_right_wheel_link"/>
    <axis rpy="0 0 0" xyz="0 -1 0"/>
  </joint>
</robot>
